2018-06-09 15:56:58 ERROR (MainThread) [homeassistant.core] Error doing job: Task exception was never retrieved
Traceback (most recent call last):
  File "/usr/lib/python3.6/site-packages/homeassistant/helpers/entity_platform.py", line 308, in _async_add_entity
    msg)
homeassistant.exceptions.HomeAssistantError: Entity id already exists: automation.___
2018-06-09 15:56:58 ERROR (MainThread) [homeassistant.core] Error doing job: Task exception was never retrieved
Traceback (most recent call last):
  File "/usr/lib/python3.6/site-packages/homeassistant/helpers/entity_platform.py", line 308, in _async_add_entity
    msg)
homeassistant.exceptions.HomeAssistantError: Entity id already exists: automation.___
